Workbook

Sheet Daftar HPP
B2: HPP D'CELUP CHICKEN CRISPY EXTRA
B4: HPP D'CELUP CHICKEN CRISPY EXTRA
B5: No | C5: Nama bahan | D5: qty | E5: satuan | F5: Jumlah | G5: Harga/gr
B6: 1 | C6: Ayam karkas Brt 1.000 / 1.100 gr | D6: 1000 | E6: gr | F6: 34000 | G6: =F6/D6 -> 34
B7: 2 | C7: Ayam Karkas 1 ekor 800/900 gr | D7: 1 | E7: Ekor | F7: 26000 | G7: =F7/D7 -> 26000
B8: 3 | C8: Bumbu Marinasi Ayam | D8: 500 | E8: gr | F8: 35150 | G8: =F8/D8 -> 70.3
B9: 4 | C9: Tepung Krispy | D9: 1000 | E9: gr | F9: 19000 | G9: =F9/D9 -> 19
B10: 5 | C10: Minyak Goreng | D10: 2000 | E10: ml | F10: 35000 | G10: =F10/D10 -> 17.5
B11: 6 | C11: Gas 3kg untuk 200 potong ayam | D11: 200 | E11: potong | F11: 22000 | G11: =F11/D11 -> 110
B12: 7 | C12: Gula Pasir | D12: 1000 | E12: gr | F12: 15000 | G12: =F12/D12 -> 15
B13: 8 | C13: Nasi (beras 1L=10 porsi) | D13: 10 | E13: porsi | F13: 12000 | G13: =F13/D13 -> 1200
B14: 9 | C14: Air Galon Isi Ulang | D14: 19000 | E14: ml | F14: 6000 | G14: =F14/D14 -> 0.31578947 | J14: Note
B15: 10 | C15: Saus Keju | D15: 1000 | E15: gr | F15: 53200 | G15: =F15/D15 -> 53.2 | K15: HPP Ayam Crispy Potong
B16: 11 | C16: Saus Barbeque Spicy | D16: 1000 | E16: gr | F16: 60800 | G16: =F16/D16 -> 60.8 | K16: HPP Ayam Crispy 1 Ekor
B17: 12 | C17: Saus Lada Hitam | D17: 1000 | E17: gr | F17: 58900 | G17: =F17/D17 -> 58.9 | K17: HPP Kentang Kriwil
B18: 13 | C18: Saus Sadis | D18: 1000 | E18: gr | F18: 61750 | G18: =F18/D18 -> 61.75 | K18: HPP Kentang French Fries
B19: 14 | C19: Saus Teriyaki | D19: 1000 | E19: gr | F19: 57000 | G19: =F19/D19 -> 57 | K19: HPP Saus DCC Extra
B20: 15 | C20: Saus sachet 8 gr Cabai / tomat | D20: 24 | E20: pcs | F20: 12000 | G20: =F20/D20 -> 500 | K20: HPP Saus Topping DCC Extra
B21: 16 | C21: Keju Mozzarella | D21: 160 | E21: gr | F21: 26000 | G21: =F21/D21 -> 162.5
B22: 17 | C22: Saus Mentai | D22: 1000 | E22: gr | F22: 66500 | G22: =F22/D22 -> 66.5
B23: 18 | C23: Saus Garlic | D23: 1000 | E23: gr | F23: 60800 | G23: =F23/D23 -> 60.8
B24: 19 | C24: Saus Carbonara | D24: 1000 | E24: gr | F24: 79800 | G24: =F24/D24 -> 79.8
B25: 20 | C25: Saus Mayo Spicy | D25: 1000 | E25: gr | F25: 76000 | G25: =F25/D25 -> 76
B26: 21 | C26: Saus Keju Bubuk | D26: 200 | E26: gr | F26: 40000 | G26: =F26/D26 -> 200
B27: 22 | C27: Kertas Nasi | D27: 1 | E27: lembar | F27: 270 | G27: =F27/D27 -> 270
B28: 23 | C28: Kentang kuning dieng | D28: 1000 | E28: gr | F28: 18000 | G28: =F28/D28 -> 18
B29: 24 | C29: Kentang French Fries | D29: 900 | E29: gr | F29: 41500 | G29: =F29/D29 -> 46.111111
B30: 25 | C30: Cabe Rawit Merah | D30: 1000 | E30: gr | F30: 40000 | G30: =F30/D30 -> 40
B31: 26 | C31: Cabe Kriting Merah | D31: 1000 | E31: gr | F31: 40000 | G31: =F31/D31 -> 40
B32: 27 | C32: Bumbu 1 (2 sdm) | D32: 500 | E32: gr | F32: 35150 | G32: =F32/D32 -> 70.3
... B40: 35 | C40: Packaging Alumunium Foil | D40: 1 | E40: pcs | F40: 2500 | G40: =F40/D40 -> 2500
B42: HPP AYAM CRISPY POTONGAN
B43: Ayam Potong 10 Rata | H43: 3. Hpp Tepung Premix Crispy
B44: 1. Hpp Marinasi Ayam Bagian Dada & Paha Atas | H44: No | I44: Nama Bahan | J44: Qty | K44: Satuan | L44: Jumlah
B45: No | C45: Nama Bahan | D45: Qty | E45: Satuan | F45: Jumlah | H45: 1 | I45: Tepung Premix Crispy | J45: 1000 | K45: gr | L45: =J45*$G$9 -> 19000
B46: 1 | C46: Ayam 10 potong | D46: 1000 | E46: gr | F46: =D46*$G$6 -> 34000 | H46: 1 kg Tepung Bisa Untuk 20 potong ayam | J46: Total | L46: =SUM(L45:L45) -> 19000
B47: 2 | C47: Bumbu Marinasi | D47: 20 | E47: gr | F47: =D47*$G$8 -> 1406 | J47: Dibagi / Potong Ayam | L47: 20
D48: Total | F48: =SUM(F46:F47) -> 35406 | J48: Hpp / Potong | L48: =L46/L47 -> 950
D49: Dibagi / Potong | F49: 10
D50: Hpp / Potong | F50: =F48/F49 -> 3540.6 | H50: 4. HPP 1 Potong Ayam Krispy Matang
...

Sheet Ayam Crispy Potong
B2: HPP & HARGA JUAL D'CELUP CHICKEN CRISPY EXTRA
B3: 1 .Ayam Krispy Original | H3: 5 .Varian Saus Sadis | N3: 9. Ayam Krispy Sambal Geprek Extra Sambal + Keju Mozzarella
B4: Ket : Ayam Crispy + Saus Sachet + Packaging Retail | H4: Ket : Ayam Crispy + Saus Sadis + Packaging Box Kecil | N4: Ket : Ayam Crispy + Sambal Geprek + Extra Sambal Geprek + Keju Mozzarella + Packaging box kecil
B5: No | C5: Item | D5: Qty | E5: Satuan | F5: Jumlah | H5: No | I5: Item | J5: Qty | K5: Satuan | L5: Jumlah | N5: No | O5: Item | P5: Qty | Q5: Satuan | R5: Jumlah
B6: 1 | C6: Ayam Crispy | D6: 1 | E6: potong | F6: =D6*'Daftar HPP'!$L$57 -> 4875.7316 | H6: 1 | I6: Ayam Crispy | J6: 1 | K6: potong | L6: =J6*'Daftar HPP'!$L$57 -> 4875.7316 | N6: 1 | O6: Ayam Crispy | P6: 1 | Q6: potong | R6: =P6*'Daftar HPP'!$L$57 -> 4875.7316
B7: 2 | C7: Saus sachet | D7: 1 | E7: pcs | F7: =D7*'Daftar HPP'!$G$20 -> 500 | H7: 2 | I7: Saus Sadis | J7: 40 | K7: gr | L7: =J7*'Daftar HPP'!$F$114 -> 1874.0829 | N7: 2 | O7: Sambal Geprek Celup | P7: 60 | Q7: gr | R7: =P7*'Daftar HPP'!$L$134 -> 2200.4203
B8: 3 | C8: Packaging Retail | D8: 1 | E8: Lembar | F8: =D8*'Daftar HPP'!$G$37 -> 388 | H8: 3 | I8: Packaging Box Kecil | J8: 1 | K8: Lembar | L8: =J8*'Daftar HPP'!$G$38 -> 810 | N8: 3 | O8: Extra Sambal Geprek | P8: 30 | Q8: gr | R8: =P8*'Daftar HPP'!$L$134 -> 1100.2101
D9: Total | F9: =SUM(F6:F8) -> 5763.7316 | J9: Total | L9: =SUM(L6:L8) -> 7559.8145 | N9: 4 | O9: Keju Mozzarella | P9: 25 | Q9: gr | R9: =P9*'Daftar HPP'!$G$21 -> 4062.5
D10: Harga Jual | F10: 10000 | J10: Harga Jual | L10: 13000 | N10: 5 | O10: Packaging Box Kecil | P10: 1 | Q10: Lembar | R10: =P10*'Daftar HPP'!$G$38 -> 810
D11: Margine | F11: =F10-F9 -> 4236.2684 | J11: Margine | L11: =L10-L9 -> 5440.1855 | P11: Total | R11: =SUM(R6:R10) -> 13048.862
P12: Harga Jual
B13: 2 .Varian Saus Keju | H13: 6 .Varian Saus BBQ Spicy | P13: Margine
B14: Ket : Ayam Crispy + Saus Keju + Packaging Box Kecil | H14: Ket : Ayam Crispy + Saus BBQ Spicy + Packaging Box Kecil
B15: No | C15: Item | D15: Qty | E15: Satuan | F15: Jumlah | H15: No | I15: Item | J15: Qty | K15: Satuan | L15: Jumlah | N15: 10. Ayam Krispy Sambal Geprek Extra Sambal + Saus Mentai
B16: 1 | C16: Ayam Crispy | D16: 1 | E16: potong | F16: =D16*'Daftar HPP'!$L$57 -> 4875.7316 | H16: 1 | I16: Ayam Crispy | J16: 1 | K16: potong | L16: =J16*'Daftar HPP'!$L$57 -> 4875.7316 | N16: Ket : Ayam Crispy + Sambal Geprek + Extra Sambal Geprek + Saus Mentai + Packaging box kecil
B17: 2 | C17: Saus Keju | D17: 50 | E17: gr | F17: =D17*'Daftar HPP'!$L$122 -> 1802.6316 | H17: 2 | I17: Saus BBQ Spicy | J17: 40 | K17: gr | L17: =J17*'Daftar HPP'!$F$123 -> 1845.2951 | N17: No | O17: Item | P17: Qty | Q17: Satuan | R17: Jumlah
B18: 3 | C18: Packaging Box Kecil | D18: 1 | E18: Lembar | F18: =D18*'Daftar HPP'!$G$38 -> 810 | H18: 3 | I18: Packaging Box Kecil | J18: 1 | K18: Lembar | L18: =J18*'Daftar HPP'!$G$38 -> 810 | N18: 1 | O18: Ayam Crispy | P18: 1 | Q18: potong | R18: =P18*'Daftar HPP'!$L$57 -> 4875.7316
D19: Total | F19: =SUM(F16:F18) -> 7488.3632 | J19: Total | L19: =SUM(L16:L18) -> 7531.0266 | N19: 2 | O19: Sambal Geprek Celup | P19: 60 | Q19: gr | R19: =P19*'Daftar HPP'!$L$134 -> 2200.4203
D20: Harga Jual | F20: 13000 | J20: Harga Jual | L20: 13000 | N20: 3 | O20: Extra Sambal Geprek | P20: 30 | Q20: gr | R20: =P20*'Daftar HPP'!$L$134 -> 1100.2101
D21: Margine | F21: =F20-F19 -> 5511.6368 | J21: Margine | L21: =L20-L19 -> 5468.9734 | N21: 4 | O21: Saus Mentai | P21: 30 | Q21: gr | R21: =P21*'Daftar HPP'!$G$22 -> 1995
N22: 5 | O22: Packaging Box Kecil | P22: 1 | Q22: Lembar | R22: =P22*'Daftar HPP'!$G$38 -> 810
B23: 3 .Varian Saus Lada Hitam | H23: 7. Varian Saus Mentai | P23: Total | R23: =SUM(R18:R22) -> 10981.362
B24: Ket : Ayam Crispy + Saus Lada Hitam + Packaging Box Kecil | H24: Ket : Ayam Crispy + Saus Mentai + Packaging Box Kecil | P24: Harga Jual
B25: No | C25: Item | D25: Qty | E25: Satuan | F25: Jumlah | H25: No | I25: Item | J25: Qty | K25: Satuan | L25: Jumlah | P25: Margine
B26: 1 | C26: Ayam Crispy | D26: 1 | E26: potong | F26: =D26*'Daftar HPP'!$L$57 -> 4875.7316 | H26: 1 | I26: Ayam Crispy | J26: 1 | K26: potong | L26: =J26*'Daftar HPP'!$L$57 -> 4875.7316
B27: 2 | C27: Saus Lada Hitam | D27: 40 | E27: gr | F27: =D27*'Daftar HPP'!$L$114 -> 1787.7193 | H27: 2 | I27: Saus Mentai | J27: 40 | K27: gr | L27: =J27*'Daftar HPP'!$G$22 -> 2660
B28: 3 | C28: Packaging Box Kecil | D28: 1 | E28: Lembar | F28: =D28*'Daftar HPP'!$G$38 -> 810 | H28: 3 | I28: Packaging Box Kecil | J28: 1 | K28: Lembar | L28: =J28*'Daftar HPP'!$G$38 -> 810
D29: Total | F29: =SUM(F26:F28) -> 7473.4509 | J29: Total | L29: =SUM(L26:L28) -> 8345.7316
D30: Harga Jual | F30: 13000 | J30: Harga Jual | L30: 13000
D31: Margine | F31: =F30-F29 -> 5526.5491 | J31: Margine | L31: =L30-L29 -> 4654.2684
B33: 4 .Varian Saus Teriyaki | H33: 8. Ayam Krispy Sambal Geprek
B34: Ket : Ayam Crispy + Saus Teriyaki + Packaging Box Kecil | H34: Ket : Ayam Crispy + Sambal Geprek + Packaging box kecil
B35: No | C35: Item | D35: Qty | E35: Satuan | F35: Jumlah | H35: No | I35: Item | J35: Qty | K35: Satuan | L35: Jumlah
B36: 1 | C36: Ayam Crispy | D36: 1 | E36: potong | F36: =D36*'Daftar HPP'!$L$57 -> 4875.7316 | H36: 1 | I36: Ayam Crispy | J36: 1 | K36: potong | L36: =J36*'Daftar HPP'!$L$57 -> 4875.7316
B37: 2 | C37: Saus Teriyaki | D37: 40 | E37: gr | F37: =D37*'Daftar HPP'!$F$131 -> 1730.1435 | H37: 2 | I37: Sambal Geprek | J37: 60 | K37: gr | L37: =J37*'Daftar HPP'!$L$134 -> 2200.4203
B38: 3 | C38: Packaging Box Kecil | D38: 1 | E38: Lembar | F38: =D38*'Daftar HPP'!$G$38 -> 810 | H38: 3 | I38: Packaging Box Kecil | J38: 1 | K38: Lembar | L38: =J38*'Daftar HPP'!$G$38 -> 810
D39: Total | F39: =SUM(F36:F38) -> 7415.8751 | J39: Total | L39: =SUM(L36:L38) -> 7886.1519
D40: Harga Jual | F40: 13000 | J40: Harga Jual | L40: 13000
D41: Margine | F41: =F40-F39 -> 5584.1249 | J41: Margine | L41: =L40-L39 -> 5113.8481
B43: HPP & HARGA JUAL D'CELUP CHICKEN CRISPY EXTRA
...

Sheet Ayam 1 Ekor
B2: HPP & HARGA JUAL D'CELUP CHICKEN CRISPY 1 EKOR (TANPA DI CELUP)
B3: 1. Ayam 1 Ekor Original
B4: Ket : Ayam 1 Ekor +Tabur Cabai + Saus Sachet + Packaging
B5: No | C5: Item | D5: Qty | E5: Satuan | F5: Jumlah
B6: 1 | C6: Ayam 1 Ekor | D6: 1 | E6: Ekor | F6: =D6*'Daftar HPP'!$L$72 -> 32526.579
B7: 2 | C7: Saus Sachet Cabe/Tomat | D7: 6 | E7: pcs | F7: =D7*'Daftar HPP'!$G$20 -> 3000
B8: 3 | C8: Packaging Ayam | D8: 1 | E8: Lembar | F8: =D8*'Daftar HPP'!$G$35 -> 1800
D9: Total | F9: =SUM(F6:F8) -> 37326.579
D10: Harga Jual | F10: 66000
D11: Margin | F11: =F10-F9 -> 28673.421
B14: HPP & HARGA JUAL D'CELUP CHICKEN CRISPY 1 EKOR + SAUS CELUP ALL VARIAN
B15: 1. Varian Celup Saus Barbeque Spicy
B16: Ket : Ayam 1 Ekor + Saus Barbeque Spicy + Packaging
B17: No | C17: Item | D17: Qty | E17: Satuan | F17: Jumlah
B18: 1 | C18: Ayam 1 Ekor | D18: 1 | E18: Ekor | F18: =D18*'Daftar HPP'!$L$72 -> 32526.579
B19: 2 | C19: Saus Barbeque Spicy | D19: 240 | E19: gr | F19: =D19*'Daftar HPP'!$F$123 -> 11071.77
B20: 3 | C20: Packaging | D20: 1 | E20: Lembar | F20: =D20*'Daftar HPP'!$G$35 -> 1800
D21: Total | F21: =SUM(F18:F20) -> 45398.349
D22: Harga Jual | F22: 76000
D23: Margine | F23: =F22-F21 -> 30601.651
B25: 1. Rincian Daftar Harga Ayam Crispy 1 Ekor
B26: No | C26: Menu | D26: Qty | E26: Satuan | F26: Hpp | G26: Margine | H26: Harga Jual
B27: 1 | C27: Ayam Crispy 1 ekor Original | D27: 1 | E27: Porsi | F27: =D27*F9 -> 37326.579 | G27: =H27-F27 -> 28673.421 | H27: =D27*F10 -> 66000
B29: 2. Rincian Daftar Harga Ayam Crispy 1 Ekor
B30: No | C30: Menu | D30: Qty | E30: Satuan | F30: Hpp | G30: Margine | H30: Harga Jual
B31: 2 | C31: Ayam Crispy Celup 1 ekor BBQ Spicy | D31: 1 | E31: Porsi | F31: =D31*F21 -> 45398.349 | G31: =H31-F31 -> 30601.651 | H31: =D31*F22 -> 76000
B33: 3. Rincian Daftar Harga Extra Saos
B34: No | C34: Menu | D34: Qty | E34: Satuan | F34: Hpp | G34: Margine | H34: Harga Jual
B35: 1 | C35: Saus Mentai | D35: 50 | E35: gr | F35: =D35*'Daftar HPP'!$G$22 -> 3325 | G35: =H35-F35 -> 5675 | H35: 9000
B36: 2 | C36: Saus Garlic | D36: 50 | E36: gr | F36: =D36*'Daftar HPP'!$G$23 -> 3040 | G36: =H36-F36 -> 5960 | H36: 9000
B37: 3 | C37: Saus Carbonara | D37: 50 | E37: gr | F37: =D37*'Daftar HPP'!$G$24 -> 3990 | G37: =H37-F37 -> 5010 | H37: 9000
B38: 4 | C38: Saus Mayo Spicy | D38: 50 | E38: gr | F38: =D38*'Daftar HPP'!$G$25 -> 3800 | G38: =H38-F38 -> 5200 | H38: 9000
B39: 5 | C39: Keju Mozzarella | D39: 50 | E39: gr | F39: =D39*'Daftar HPP'!$G$21 -> 8125 | G39: =H39-F39 -> 3875 | H39: 12000

Sheet Kentang Kriwil
B2: HPP DAN HARGA JUAL KENTANG KRIWIL
B3: PORSI REGULER | H3: PORSI LARGE
B4: 1. Kentang Kriwil Original Saus Sachet | H4: 1. Kentang Kriwil Original Saus Sachet
B5: Ket : Kentang Kriwil + Saus Sadis + Packaging Box Kecil | H5: Ket : Kentang Kriwil + Saus Sadis + Packaging Box Kecil
B6: No | C6: Item | D6: Qty | E6: Satuan | F6: Jumlah | H6: No | I6: Item | J6: Qty | K6: Satuan | L6: Jumlah
B7: 1 | C7: Kentang Kriwil | D7: 1 | E7: Porsi | F7: =D7*'Daftar HPP'!$L$81 -> 3763.1793 | H7: 1 | I7: Kentang Kriwil | J7: 1 | K7: Porsi | L7: =J7*$L$38 -> 7218.4638
B8: 2 | C8: Saus sachet | D8: 1 | E8: gr | F8: =D8*'Daftar HPP'!$G$20 -> 500 | H8: 2 | I8: Saus sachet | J8: 1 | K8: gr | L8: =J8*'Daftar HPP'!$G$20 -> 500
B9: 3 | C9: Packaging Retail | D9: 1 | E9: pcs | F9: =D9*'Daftar HPP'!$G$37 -> 388 | H9: 3 | I9: Packaging Box Kecil | J9: 1 | K9: pcs | L9: =J9*'Daftar HPP'!$G$38 -> 810
D10: Total | F10: =SUM(F7:F9) -> 4651.1793 | J10: Total | L10: =SUM(L7:L9) -> 8663.4638
D11: Harga Jual | F11: 8000 | J11: Harga Jual | L11: 14000
D12: Margine | F12: =F11-F10 -> 3348.8207 | J12: Margine | L12: =L11-L10 -> 5336.5362
B15: 2. Kentang Kriwil Saus Sadis | H15: 2. Kentang Kriwil Saus Sadis
B16: Ket : Kentang Kriwil + Saus Sadis + Packaging Box Kecil | H16: Ket : Kentang Kriwil + Saus Sadis + Packaging Box Kecil
B17: No | C17: Item | D17: Qty | E17: Satuan | F17: Jumlah | H17: No | I17: Item | J17: Qty | K17: Satuan | L17: Jumlah
B18: 1 | C18: Kentang Kriwil | D18: 1 | E18: Porsi | F18: =D18*'Daftar HPP'!$L$81 -> 3763.1793 | H18: 1 | I18: Kentang Kriwil | J18: 1 | K18: Porsi | L18: =J18*$L$38 -> 7218.4638
B19: 2 | C19: Saus Sadis | D19: 25 | E19: gr | F19: =D19*'Daftar HPP'!$F$114 -> 1171.3018 | H19: 2 | I19: Saus Sadis | J19: 50 | K19: gr | L19: =J19*'Daftar HPP'!$F$114 -> 2342.6037
B20: 3 | C20: Packaging Retail | D20: 1 | E20: pcs | F20: =D20*'Daftar HPP'!$G$37 -> 388 | H20: 3 | I20: Packaging Box Kecil | J20: 1 | K20: pcs | L20: =J20*'Daftar HPP'!$G$38 -> 810
D21: Total | F21: =SUM(F18:F20) -> 5322.4811 | J21: Total | L21: =SUM(L18:L20) -> 10506.068
D22: Harga Jual | F22: 10000 | J22: Harga Jual | L22: 16000
D23: Margine | F23: =F22-F21 -> 4677.5189 | J23: Margine | L23: =L22-L21 -> 5493.9325
B25: 3. Kentang Kriwil Saus Barbeque Spicy | H25: 3. Kentang Kriwil Saus Barbeque Spicy
B26: Ket : Kentang Kriwil + Saus Barbeque Spicy + Packaging Box Kecil | H26: Ket : Kentang Kriwil + Saus Barbeque Spicy + Packaging Box Kecil
B27: No | C27: Item | D27: Qty | E27: Satuan | F27: Jumlah | H27: No | I27: Item | J27: Qty | K27: Satuan | L27: Jumlah
B28: 1 | C28: Kentang Kriwil | D28: 1 | E28: Porsi | F28: =D28*'Daftar HPP'!$L$81 -> 3763.1793 | H28: 1 | I28: Kentang Kriwil | J28: 1 | K28: Porsi | L28: =J28*$L$38 -> 7218.4638
B29: 2 | C29: Saus Barbeque Spicy | D29: 25 | E29: gr | F29: =D29*'Daftar HPP'!$F$123 -> 1153.3094 | H29: 2 | I29: Saus Barbeque Spicy | J29: 50 | K29: gr | L29: =J29*'Daftar HPP'!$F$123 -> 2306.6188
B30: 3 | C30: Packaging Retail | D30: 1 | E30: pcs | F30: =D30*'Daftar HPP'!$G$37 -> 388 | H30: 3 | I30: Packaging Box Kecil | J30: 1 | K30: pcs | L30: =J30*'Daftar HPP'!$G$38 -> 810
D31: Total | F31: =SUM(F28:F30) -> 5304.4887 | J31: Total | L31: =SUM(L28:L30) -> 10470.083
D32: Harga Jual | F32: 10000 | J32: Harga Jual | L32: 16000
D33: Margine | F33: =F32-F31 -> 4695.5113 | J33: Margine | L33: =L32-L31 -> 5529.9173
B35: 4. Kentang Kriwil Saus Teriyaki | H35: 4. Kentang Kriwil Saus Teriyaki
B36: Ket : Kentang Kriwil + Saus Sadis + Packaging Box Kecil | H36: Ket : Kentang Kriwil + Saus Sadis + Packaging Box Kecil
B37: No | C37: Item | D37: Qty | E37: Satuan | F37: Jumlah | H37: No | I37: Item | J37: Qty | K37: Satuan | L37: Jumlah
B38: 1 | C38: Kentang Kriwil | D38: 1 | E38: Porsi | F38: =D38*'Daftar HPP'!$L$81 -> 3763.1793 | H38: 1 | I38: Kentang Kriwil | J38: 1 | K38: Porsi | L38: =J38*$L$38 -> 7218.4638
B39: 2 | C39: Saus Teriyaki | D39: 25 | E39: gr | F39: =D39*'Daftar HPP'!$F$131 -> 1081.3397 | H39: 2 | I39: Saus Teriyaki | J39: 50 | K39: gr | L39: =J39*'Daftar HPP'!$F$131 -> 2162.6794
B40: 3 | C40: Packaging Retail | D40: 1 | E40: pcs | F40: =D40*'Daftar HPP'!$G$37 -> 388 | H40: 3 | I40: Packaging Box Kecil | J40: 1 | K40: pcs | L40: =J40*'Daftar HPP'!$G$38 -> 810
D41: Total | F41: =SUM(F38:F40) -> 5232.519 | J41: Total | L41: =SUM(L38:L40) -> 10326.143
D42: Harga Jual | F42: 10000 | J42: Harga Jual | L42: 16000
D43: Margine | F43: =F42-F41 -> 4767.481 | J43: Margine | L43: =L42-L41 -> 5673.8567
B45: 5. Kentang Kriwil Saus Lada Hitam | H45: 5. Kentang Kriwil Saus Lada Hitam
B46: Ket : Kentang Kriwil + Saus Lada Hitam + Packaging Box Kecil | H46: Ket : Kentang Kriwil + Saus Lada Hitam + Packaging Box Kecil
...

Sheet Cut Series (Ayam +  Kentang
B2: HPP DAN HARGA JUAL DCC CUT TRAY (AYAM CRISPY ORIGINAL + KENTANG FRENCH FRIES) STANDAR | T2: HPP DAN HARGA JUAL DCC CUT TRAY (AYAM CRISPY ORIGINAL + KENTANG FRENCH FRIES) DOUBLE
B3: 1. DCC CUT TRAY SAUS KEJU + SAUS MENTAI | H3: 5. DCC CUT TRAY MENTAI + SAUS CARBONARA | N3: 9. DCC CUT TRAY SAUS MAYO SPICY + SAUS GARLIC | T3: 1. DCC CUT TRAY SAUS KEJU + SAUS MENTAI | Z3: 5. DCC CUT TRAY MENTAI + SAUS CARBONARA | AF3: 9. DCC CUT TRAY SAUS MAYO SPICY + SAUS GARLIC
B4: No | C4: Item | D4: Qty | E4: Satuan | F4: Jumlah | H4: No | I4: Item | J4: Qty | K4: Satuan | L4: Jumlah | N4: No | O4: Item | P4: Qty | Q4: Satuan | R4: Jumlah | T4: No | U4: Item | V4: Qty | W4: Satuan | X4: Jumlah | Z4: No | AA4: Item | AB4: Qty | AC4: Satuan | AD4: Jumlah | AF4: No | AG4: Item | AH4: Qty | AI4: Satuan | AJ4: Jumlah
B5: 1 | C5: Ayam Crispy | D5: 1 | E5: Potong | F5: =D5*'Daftar HPP'!$L$57 -> 4875.7316 | H5: 1 | I5: Ayam Crispy | J5: 1 | K5: Potong | L5: =J5*'Daftar HPP'!$L$57 -> 4875.7316 | N5: 1 | O5: Ayam Crispy | P5: 1 | Q5: Potong | R5: =P5*'Daftar HPP'!$L$57 -> 4875.7316 | T5: 1 | U5: Ayam Crispy | V5: 2 | W5: Potong | X5: =V5*'Daftar HPP'!$L$57 -> 9751.4632 | Z5: 1 | AA5: Ayam Crispy | AB5: 2 | AC5: Potong | AD5: =AB5*'Daftar HPP'!$L$57 -> 9751.4632 | AF5: 1 | AG5: Ayam Crispy | AH5: 2 | AI5: Potong | AJ5: =AH5*'Daftar HPP'!$L$57 -> 9751.4632
B6: 2 | C6: Kentang French Fries (100 gr) | D6: 1 | E6: Porsi | F6: =D6*'Daftar HPP'!$F$105 -> 7659.7901 | H6: 2 | I6: Kentang French Fries (100 gr) | J6: 1 | K6: Porsi | L6: =J6*'Daftar HPP'!$F$105 -> 7659.7901 | N6: 2 | O6: Kentang French Fries (100 gr) | P6: 1 | Q6: Porsi | R6: =P6*'Daftar HPP'!$F$105 -> 7659.7901 | T6: 2 | U6: Kentang French Fries (150 gr) | V6: 1 | W6: Porsi | X6: =V6*'Daftar HPP'!$L$96 -> 11489.685 | Z6: 2 | AA6: Kentang French Fries (150 gr) | AB6: 1 | AC6: Porsi | AD6: =AB6*'Daftar HPP'!$L$96 -> 11489.685 | AF6: 2 | AG6: Kentang French Fries (150 gr) | AH6: 1 | AI6: Porsi | AJ6: =AH6*'Daftar HPP'!$L$96 -> 11489.685
B7: 3 | C7: Saus Keju | D7: 30 | E7: gr | F7: =D7*'Daftar HPP'!$F$152 -> 2093.9588 | H7: 3 | I7: Saus Mentai | J7: 30 | K7: gr | L7: =J7*'Daftar HPP'!$G$22 -> 1995 | N7: 3 | O7: Saus Mayo Spicy | P7: 30 | Q7: gr | R7: =P7*'Daftar HPP'!$L$152 -> 2144.1037 | T7: 3 | U7: Saus Keju | V7: 30 | W7: gr | X7: =V7*'Daftar HPP'!$F$152 -> 2093.9588 | Z7: 3 | AA7: Saus Mentai | AB7: 30 | AC7: gr | AD7: =AB7*'Daftar HPP'!$G$22 -> 1995 | AF7: 3 | AG7: Saus Mayo Spicy | AH7: 30 | AI7: gr | AJ7: =AH7*'Daftar HPP'!$L$152 -> 2144.1037
B8: 4 | C8: Saus Mentai | D8: 30 | E8: gr | F8: =D8*'Daftar HPP'!$G$22 -> 1995 | H8: 4 | I8: Saus Carbonara | J8: 30 | K8: gr | L8: =J8*'Daftar HPP'!$F$143 -> 2146.3497 | N8: 4 | O8: Saus Garlic | P8: 30 | Q8: gr | R8: =P8*'Daftar HPP'!$L$143 -> 1647.4064 | T8: 4 | U8: Saus Mentai | V8: 30 | W8: gr | X8: =V8*'Daftar HPP'!$G$22 -> 1995 | Z8: 4 | AA8: Saus Carbonara | AB8: 30 | AC8: gr | AD8: =AB8*'Daftar HPP'!$F$143 -> 2146.3497 | AF8: 4 | AG8: Saus Garlic | AH8: 30 | AI8: gr | AJ8: =AH8*'Daftar HPP'!$L$143 -> 1647.4064
B9: 5 | C9: Bubuk Cabai Kasar | D9: 1 | E9: gr | F9: =D9*'Daftar HPP'!$G$33 -> 100 | H9: 5 | I9: Bubuk Cabai Kasar | J9: 1 | K9: gr | L9: =J9*'Daftar HPP'!$G$33 -> 100 | N9: 5 | O9: Bubuk Cabai Kasar | P9: 1 | Q9: gr | R9: =P9*'Daftar HPP'!$G$33 -> 100 | T9: 5 | U9: Bubuk Cabai Kasar | V9: 1 | W9: gr | X9: =V9*'Daftar HPP'!$G$33 -> 100 | Z9: 5 | AA9: Bubuk Cabai Kasar | AB9: 1 | AC9: gr | AD9: =AB9*'Daftar HPP'!$G$33 -> 100 | AF9: 5 | AG9: Bubuk Cabai Kasar | AH9: 1 | AI9: gr | AJ9: =AH9*'Daftar HPP'!$G$33 -> 100
B10: 6 | C10: Packaging Tray | D10: 1 | E10: lembar | F10: =D10*'Daftar HPP'!$G$39 -> 1100 | H10: 6 | I10: Packaging Tray | J10: 1 | K10: lembar | L10: =J10*'Daftar HPP'!$G$39 -> 1100 | N10: 6 | O10: Packaging Tray | P10: 1 | Q10: lembar | R10: =P10*'Daftar HPP'!$G$39 -> 1100 | T10: 6 | U10: Packaging Tray | V10: 1 | W10: lembar | X10: =V10*'Daftar HPP'!$G$39 -> 1100 | Z10: 6 | AA10: Packaging Tray | AB10: 1 | AC10: lembar | AD10: =AB10*'Daftar HPP'!$G$39 -> 1100 | AF10: 6 | AG10: Packaging Tray | AH10: 1 | AI10: lembar | AJ10: =AH10*'Daftar HPP'!$G$39 -> 1100
D11: Total | F11: =SUM(F5:F10) -> 17824.48 | J11: Total | L11: =SUM(L5:L10) -> 17876.871 | P11: Total | R11: =SUM(R5:R10) -> 17527.032 | V11: Total | X11: =SUM(X5:X10) -> 26530.107 | AB11: Total | AD11: =SUM(AD5:AD10) -> 26582.498 | AH11: Total | AJ11: =SUM(AJ5:AJ10) -> 26232.658
D12: Harga Jual | F12: 29000 | J12: Harga Jual | L12: 29000 | P12: Harga Jual | R12: 29000 | V12: Harga Jual | X12: 43000 | AB12: Harga Jual | AD12: 43000 | AH12: Harga Jual | AJ12: 43000
D13: Margine | F13: =F12-F11 -> 11175.52 | J13: Margine | L13: =L12-L11 -> 11123.129 | P13: Margine | R13: =R12-R11 -> 11472.968 | V13: Margine | X13: =X12-X11 -> 16469.893 | AB13: Margine | AD13: =AD12-AD11 -> 16417.502 | AH13: Margine | AJ13: =AJ12-AJ11 -> 16767.342
B15: 2. DCC CUT TRAY SAUS KEJU + SAUS CARBONARA | H15: 6. DCC CUT TRAY SAUS MENTAI + SAUS MAYO SPICY | N15: 10. DCC CUT TRAY SAUS CARBONARA + SAUS GARLIC | T15: 2. DCC CUT TRAY SAUS KEJU + SAUS CARBONARA | Z15: 6. DCC CUT TRAY SAUS MENTAI + SAUS MAYO SPICY | AF15: 10. DCC CUT TRAY SAUS CARBONARA + SAUS GARLIC
B16: No | C16: Item | D16: Qty | E16: Satuan | F16: Jumlah | H16: No | I16: Item | J16: Qty | K16: Satuan | L16: Jumlah | N16: No | O16: Item | P16: Qty | Q16: Satuan | R16: Jumlah | T16: No | U16: Item | V16: Qty | W16: Satuan | X16: Jumlah | Z16: No | AA16: Item | AB16: Qty | AC16: Satuan | AD16: Jumlah | AF16: No | AG16: Item | AH16: Qty | AI16: Satuan | AJ16: Jumlah
B17: 1 | C17: Ayam Crispy | D17: 1 | E17: Potong | F17: =D17*'Daftar HPP'!$L$57 -> 4875.7316 | H17: 1 | I17: Ayam Crispy | J17: 1 | K17: Potong | L17: =J17*'Daftar HPP'!$L$57 -> 4875.7316 | N17: 1 | O17: Ayam Crispy | P17: 1 | Q17: Potong | R17: =P17*'Daftar HPP'!$L$57 -> 4875.7316 | T17: 1 | U17: Ayam Crispy | V17: 2 | W17: Potong | X17: =V17*'Daftar HPP'!$L$57 -> 9751.4632 | Z17: 1 | AA17: Ayam Crispy | AB17: 2 | AC17: Potong | AD17: =AB17*'Daftar HPP'!$L$57 -> 9751.4632 | AF17: 1 | AG17: Ayam Crispy | AH17: 2 | AI17: Potong | AJ17: =AH17*'Daftar HPP'!$L$57 -> 9751.4632
B18: 2 | C18: Kentang French Fries (100 gr) | D18: 1 | E18: Porsi | F18: =D18*'Daftar HPP'!$F$105 -> 7659.7901 | H18: 2 | I18: Kentang French Fries (100 gr) | J18: 1 | K18: Porsi | L18: =J18*'Daftar HPP'!$F$105 -> 7659.7901 | N18: 2 | O18: Kentang French Fries (100 gr) | P18: 1 | Q18: Porsi | R18: =P18*'Daftar HPP'!$F$105 -> 7659.7901 | T18: 2 | U18: Kentang French Fries (150 gr) | V18: 1 | W18: Porsi | X18: =V18*'Daftar HPP'!$L$96 -> 11489.685 | Z18: 2 | AA18: Kentang French Fries (150 gr) | AB18: 1 | AC18: Porsi | AD18: =AB18*'Daftar HPP'!$L$96 -> 11489.685 | AF18: 2 | AG18: Kentang French Fries (150 gr) | AH18: 1 | AI18: Porsi | AJ18: =AH18*'Daftar HPP'!$L$96 -> 11489.685
B19: 3 | C19: Saus Keju | D19: 30 | E19: gr | F19: =D19*'Daftar HPP'!$F$152 -> 2093.9588 | H19: 3 | I19: Saus Mentai | J19: 30 | K19: gr | L19: =J19*'Daftar HPP'!$G$22 -> 1995 | N19: 3 | O19: Saus Garlic | P19: 30 | Q19: gr | R19: =P19*'Daftar HPP'!$L$143 -> 1647.4064 | T19: 3 | U19: Saus Keju | V19: 30 | W19: gr | X19: =V19*'Daftar HPP'!$F$152 -> 2093.9588 | Z19: 3 | AA19: Saus Mentai | AB19: 30 | AC19: gr | AD19: =AB19*'Daftar HPP'!$G$22 -> 1995 | AF19: 3 | AG19: Saus Garlic | AH19: 30 | AI19: gr | AJ19: =AH19*'Daftar HPP'!$L$143 -> 1647.4064
B20: 4 | C20: Saus Carbonara | D20: 30 | E20: gr | F20: =D20*'Daftar HPP'!$F$143 -> 2146.3497 | H20: 4 | I20: Saus Mayo Spicy | J20: 30 | K20: gr | L20: =J20*'Daftar HPP'!$L$152 -> 2144.1037 | N20: 4 | O20: Saus Carbonara | P20: 30 | Q20: gr | R20: =P20*'Daftar HPP'!$F$143 -> 2146.3497 | T20: 4 | U20: Saus Carbonara | V20: 30 | W20: gr | X20: =V20*'Daftar HPP'!$F$143 -> 2146.3497 | Z20: 4 | AA20: Saus Mayo Spicy | AB20: 30 | AC20: gr | AD20: =AB20*'Daftar HPP'!$L$152 -> 2144.1037 | AF20: 4 | AG20: Saus Carbonara | AH20: 30 | AI20: gr | AJ20: =AH20*'Daftar HPP'!$F$143 -> 2146.3497
B21: 5 | C21: Bubuk Cabai Kasar | D21: 1 | E21: gr | F21: =D21*'Daftar HPP'!$G$33 -> 100 | H21: 5 | I21: Bubuk Cabai Kasar | J21: 1 | K21: gr | L21: =J21*'Daftar HPP'!$G$33 -> 100 | N21: 5 | O21: Bubuk Cabai Kasar | P21: 1 | Q21: gr | R21: =P21*'Daftar HPP'!$G$33 -> 100 | T21: 5 | U21: Bubuk Cabai Kasar | V21: 1 | W21: gr | X21: =V21*'Daftar HPP'!$G$33 -> 100 | Z21: 5 | AA21: Bubuk Cabai Kasar | AB21: 1 | AC21: gr | AD21: =AB21*'Daftar HPP'!$G$33 -> 100 | AF21: 5 | AG21: Bubuk Cabai Kasar | AH21: 1 | AI21: gr | AJ21: =AH21*'Daftar HPP'!$G$33 -> 100
B22: 6 | C22: Packaging Tray | D22: 1 | E22: lembar | F22: =D22*'Daftar HPP'!$G$39 -> 1100 | H22: 6 | I22: Packaging Tray | J22: 1 | K22: lembar | L22: =J22*'Daftar HPP'!$G$39 -> 1100 | N22: 6 | O22: Packaging Tray | P22: 1 | Q22: lembar | R22: =P22*'Daftar HPP'!$G$39 -> 1100 | T22: 6 | U22: Packaging Tray | V22: 1 | W22: lembar | X22: =V22*'Daftar HPP'!$G$39 -> 1100 | Z22: 6 | AA22: Packaging Tray | AB22: 1 | AC22: lembar | AD22: =AB22*'Daftar HPP'!$G$39 -> 1100 | AF22: 6 | AG22: Packaging Tray | AH22: 1 | AI22: lembar | AJ22: =AH22*'Daftar HPP'!$G$39 -> 1100
D23: Total | F23: =SUM(F17:F22) -> 17975.83 | J23: Total | L23: =SUM(L17:L22) -> 17874.625 | P23: Total | R23: =SUM(R17:R22) -> 17529.278 | V23: Total | X23: =SUM(X17:X22) -> 26681.457 | AB23: Total | AD23: =SUM(AD17:AD22) -> 26580.252 | AH23: Total | AJ23: =SUM(AJ17:AJ22) -> 26234.904
D24: Harga Jual | F24: 29000 | J24: Harga Jual | L24: 29000 | P24: Harga Jual | R24: 29000 | V24: Harga Jual | X24: 43000 | AB24: Harga Jual | AD24: 43000 | AH24: Harga Jual | AJ24: 43000
D25: Margine | F25: =F24-F23 -> 11024.17 | J25: Margine | L25: =L24-L23 -> 11125.375 | P25: Margine | R25: =R24-R23 -> 11470.722 | V25: Margine | X25: =X24-X23 -> 16318.543 | AB25: Margine | AD25: =AD24-AD23 -> 16419.748 | AH25: Margine | AJ25: =AJ24-AJ23 -> 16765.096
B27: 3. DCC CUT TRAY SAUS KEJU + SAUS MAYO SPICY | H27: 7. DCC CUT TRAY SAUS MENTAI + SAUS GARLIC | T27: 3. DCC CUT TRAY SAUS KEJU + SAUS MAYO SPICY | Z27: 7. DCC CUT TRAY SAUS MENTAI + SAUS GARLIC
B28: No | C28: Item | D28: Qty | E28: Satuan | F28: Jumlah | H28: No | I28: Item | J28: Qty | K28: Satuan | L28: Jumlah | T28: No | U28: Item | V28: Qty | W28: Satuan | X28: Jumlah | Z28: No | AA28: Item | AB28: Qty | AC28: Satuan | AD28: Jumlah
B29: 1 | C29: Ayam Crispy | D29: 1 | E29: Potong | F29: =D29*'Daftar HPP'!$L$57 -> 4875.7316 | H29: 1 | I29: Ayam Crispy | J29: 1 | K29: Potong | L29: =J29*'Daftar HPP'!$L$57 -> 4875.7316 | T29: 1 | U29: Ayam Crispy | V29: 2 | W29: Potong | X29: =V29*'Daftar HPP'!$L$57 -> 9751.4632 | Z29: 1 | AA29: Ayam Crispy | AB29: 2 | AC29: Potong | AD29: =AB29*'Daftar HPP'!$L$57 -> 9751.4632
B30: 2 | C30: Kentang French Fries (100 gr) | D30: 1 | E30: Porsi | F30: =D30*'Daftar HPP'!$F$105 -> 7659.7901 | H30: 2 | I30: Kentang French Fries (100 gr) | J30: 1 | K30: Porsi | L30: =J30*'Daftar HPP'!$F$105 -> 7659.7901 | T30: 2 | U30: Kentang French Fries (150 gr) | V30: 1 | W30: Porsi | X30: =V30*'Daftar HPP'!$L$96 -> 11489.685 | Z30: 2 | AA30: Kentang French Fries (150 gr) | AB30: 1 | AC30: Porsi | AD30: =AB30*'Daftar HPP'!$L$96 -> 11489.685
B31: 3 | C31: Saus Keju | D31: 30 | E31: gr | F31: =D31*'Daftar HPP'!$F$152 -> 2093.9588 | H31: 3 | I31: Saus Mentai | J31: 30 | K31: gr | L31: =J31*'Daftar HPP'!$G$22 -> 1995 | T31: 3 | U31: Saus Keju | V31: 30 | W31: gr | X31: =V31*'Daftar HPP'!$F$152 -> 2093.9588 | Z31: 3 | AA31: Saus Mentai | AB31: 30 | AC31: gr | AD31: =AB31*'Daftar HPP'!$G$22 -> 1995
B32: 4 | C32: Saus Mayo Spicy | D32: 30 | E32: gr | F32: =D32*'Daftar HPP'!$L$152 -> 2144.1037 | H32: 4 | I32: Saus Garlic | J32: 30 | K32: gr | L32: =J32*'Daftar HPP'!$L$143 -> 1647.4064 | T32: 4 | U32: Saus Mayo Spicy | V32: 30 | W32: gr | X32: =V32*'Daftar HPP'!$L$152 -> 2144.1037 | Z32: 4 | AA32: Saus Garlic | AB32: 30 | AC32: gr | AD32: =AB32*'Daftar HPP'!$L$143 -> 1647.4064
B33: 5 | C33: Bubuk Cabai Kasar | D33: 1 | E33: gr | F33: =D33*'Daftar HPP'!$G$33 -> 100 | H33: 5 | I33: Bubuk Cabai Kasar | J33: 1 | K33: gr | L33: =J33*'Daftar HPP'!$G$33 -> 100 | T33: 5 | U33: Bubuk Cabai Kasar | V33: 1 | W33: gr | X33: =V33*'Daftar HPP'!$G$33 -> 100 | Z33: 5 | AA33: Bubuk Cabai Kasar | AB33: 1 | AC33: gr | AD33: =AB33*'Daftar HPP'!$G$33 -> 100
B34: 6 | C34: Packaging Tray | D34: 1 | E34: lembar | F34: =D34*'Daftar HPP'!$G$39 -> 1100 | H34: 6 | I34: Packaging Tray | J34: 1 | K34: lembar | L34: =J34*'Daftar HPP'!$G$39 -> 1100 | T34: 6 | U34: Packaging Tray | V34: 1 | W34: lembar | X34: =V34*'Daftar HPP'!$G$39 -> 1100 | Z34: 6 | AA34: Packaging Tray | AB34: 1 | AC34: lembar | AD34: =AB34*'Daftar HPP'!$G$39 -> 1100
D35: Total | F35: =SUM(F29:F34) -> 17973.584 | J35: Total | L35: =SUM(L29:L34) -> 17377.928 | V35: Total | X35: =SUM(X29:X34) -> 26679.211 | AB35: Total | AD35: =SUM(AD29:AD34) -> 26083.555
D36: Harga Jual | F36: 29000 | J36: Harga Jual | L36: 29000 | V36: Harga Jual | X36: 43000 | AB36: Harga Jual | AD36: 43000
D37: Margine | F37: =F36-F35 -> 11026.416 | J37: Margine | L37: =L36-L35 -> 11622.072 | V37: Margine | X37: =X36-X35 -> 16320.789 | AB37: Margine | AD37: =AD36-AD35 -> 16916.445
B39: 4. DCC CUT TRAY SAUS KEJU + SAUS GARLIC | H39: 8. DCC CUT TRAY SAUS MAYO SPICY + SAUS CARBONARA | T39: 4. DCC CUT TRAY SAUS KEJU + SAUS GARLIC | Z39: 8. DCC CUT TRAY SAUS MAYO SPICY + SAUS CARBONARA
B40: No | C40: Item | D40: Qty | E40: Satuan | F40: Jumlah | H40: No | I40: Item | J40: Qty | K40: Satuan | L40: Jumlah | T40: No | U40: Item | V40: Qty | W40: Satuan | X40: Jumlah | Z40: No | AA40: Item | AB40: Qty | AC40: Satuan | AD40: Jumlah
B41: 1 | C41: Ayam Crispy | D41: 1 | E41: Potong | F41: =D41*'Daftar HPP'!$L$57 -> 4875.7316 | H41: 1 | I41: Ayam Crispy | J41: 1 | K41: Potong | L41: =J41*'Daftar HPP'!$L$57 -> 4875.7316 | T41: 1 | U41: Ayam Crispy | V41: 2 | W41: Potong | X41: =V41*'Daftar HPP'!$L$57 -> 9751.4632 | Z41: 1 | AA41: Ayam Crispy | AB41: 2 | AC41: Potong | AD41: =AB41*'Daftar HPP'!$L$57 -> 9751.4632
B42: 2 | C42: Kentang French Fries (100 gr) | D42: 1 | E42: Porsi | F42: =D42*'Daftar HPP'!$F$105 -> 7659.7901 | H42: 2 | I42: Kentang French Fries (100 gr) | J42: 1 | K42: Porsi | L42: =J42*'Daftar HPP'!$F$105 -> 7659.7901 | T42: 2 | U42: Kentang French Fries (150 gr) | V42: 1 | W42: Porsi | X42: =V42*'Daftar HPP'!$L$96 -> 11489.685 | Z42: 2 | AA42: Kentang French Fries (150 gr) | AB42: 1 | AC42: Porsi | AD42: =AB42*'Daftar HPP'!$L$96 -> 11489.685
B43: 3 | C43: Saus Keju | D43: 30 | E43: gr | F43: =D43*'Daftar HPP'!$F$152 -> 2093.9588 | H43: 3 | I43: Saus Mayo Spicy | J43: 30 | K43: gr | L43: =J43*'Daftar HPP'!$L$152 -> 2144.1037 | T43: 3 | U43: Saus Keju | V43: 30 | W43: gr | X43: =V43*'Daftar HPP'!$F$152 -> 2093.9588 | Z43: 3 | AA43: Saus Mayo Spicy | AB43: 30 | AC43: gr | AD43: =AB43*'Daftar HPP'!$L$152 -> 2144.1037
B44: 4 | C44: Saus Garlic | D44: 30 | E44: gr | F44: =D44*'Daftar HPP'!$L$143 -> 1647.4064 | H44: 4 | I44: Saus Carbonara | J44: 30 | K44: gr | L44: =J44*'Daftar HPP'!$F$143 -> 2146.3497 | T44: 4 | U44: Saus Garlic | V44: 30 | W44: gr | X44: =V44*'Daftar HPP'!$L$143 -> 1647.4064 | Z44: 4 | AA44: Saus Carbonara | AB44: 30 | AC44: gr | AD44: =AB44*'Daftar HPP'!$F$143 -> 2146.3497
...

Sheet Cut Series (Ayam +  Nasi)
B2: HPP DAN HARGA JUAL DCC CUT TRAY (AYAM CRISPY ORIGINAL + NASI) STANDAR | T2: HPP DAN HARGA JUAL DCC CUT TRAY (AYAM CRISPY ORIGINAL + NASI) DOUBLE
B3: 1. DCC CUT TRAY SAUS KEJU + SAUS MENTAI | H3: 5. DCC CUT TRAY MENTAI + SAUS CARBONARA | N3: 9. DCC CUT TRAY SAUS MAYO SPICY + SAUS GARLIC | T3: 1. DCC CUT TRAY SAUS KEJU + SAUS MENTAI | Z3: 5. DCC CUT TRAY MENTAI + SAUS CARBONARA | AF3: 9. DCC CUT TRAY SAUS MAYO SPICY + SAUS GARLIC
B4: No | C4: Item | D4: Qty | E4: Satuan | F4: Jumlah | H4: No | I4: Item | J4: Qty | K4: Satuan | L4: Jumlah | N4: No | O4: Item | P4: Qty | Q4: Satuan | R4: Jumlah | T4: No | U4: Item | V4: Qty | W4: Satuan | X4: Jumlah | Z4: No | AA4: Item | AB4: Qty | AC4: Satuan | AD4: Jumlah | AF4: No | AG4: Item | AH4: Qty | AI4: Satuan | AJ4: Jumlah
B5: 1 | C5: Ayam Crispy | D5: 1 | E5: Potong | F5: =D5*'Daftar HPP'!$L$57 -> 4875.7316 | H5: 1 | I5: Ayam Crispy | J5: 1 | K5: Potong | L5: =J5*'Daftar HPP'!$L$57 -> 4875.7316 | N5: 1 | O5: Ayam Crispy | P5: 1 | Q5: Potong | R5: =P5*'Daftar HPP'!$L$57 -> 4875.7316 | T5: 1 | U5: Ayam Crispy | V5: 2 | W5: Potong | X5: =V5*'Daftar HPP'!$L$57 -> 9751.4632 | Z5: 1 | AA5: Ayam Crispy | AB5: 2 | AC5: Potong | AD5: =AB5*'Daftar HPP'!$L$57 -> 9751.4632 | AF5: 1 | AG5: Ayam Crispy | AH5: 2 | AI5: Potong | AJ5: =AH5*'Daftar HPP'!$L$57 -> 9751.4632
B6: 2 | C6: Nasi | D6: 1 | E6: Porsi | F6: =D6*'Daftar HPP'!$G$13 -> 1200 | H6: 2 | I6: Nasi | J6: 1 | K6: Porsi | L6: =J6*'Daftar HPP'!$G$13 -> 1200 | N6: 2 | O6: Nasi | P6: 1 | Q6: Porsi | R6: =P6*'Daftar HPP'!$G$13 -> 1200 | T6: 2 | U6: Nasi | V6: 1 | W6: Porsi | X6: =V6*'Daftar HPP'!$G$13 -> 1200 | Z6: 2 | AA6: Nasi | AB6: 1 | AC6: Porsi | AD6: =AB6*'Daftar HPP'!$G$13 -> 1200 | AF6: 2 | AG6: Nasi | AH6: 1 | AI6: Porsi | AJ6: =AH6*'Daftar HPP'!$G$13 -> 1200
B7: 3 | C7: Saus Keju | D7: 30 | E7: gr | F7: =D7*'Daftar HPP'!$F$152 -> 2093.9588 | H7: 3 | I7: Saus Mentai | J7: 30 | K7: gr | L7: =J7*'Daftar HPP'!$G$22 -> 1995 | N7: 3 | O7: Saus Mayo Spicy | P7: 30 | Q7: gr | R7: =P7*'Daftar HPP'!$L$152 -> 2144.1037 | T7: 3 | U7: Saus Keju | V7: 30 | W7: gr | X7: =V7*'Daftar HPP'!$F$152 -> 2093.9588 | Z7: 3 | AA7: Saus Mentai | AB7: 30 | AC7: gr | AD7: =AB7*'Daftar HPP'!$G$22 -> 1995 | AF7: 3 | AG7: Saus Mayo Spicy | AH7: 30 | AI7: gr | AJ7: =AH7*'Daftar HPP'!$L$152 -> 2144.1037
B8: 4 | C8: Saus Mentai | D8: 30 | E8: gr | F8: =D8*'Daftar HPP'!$G$22 -> 1995 | H8: 4 | I8: Saus Carbonara | J8: 30 | K8: gr | L8: =J8*'Daftar HPP'!$F$143 -> 2146.3497 | N8: 4 | O8: Saus Garlic | P8: 30 | Q8: gr | R8: =P8*'Daftar HPP'!$L$143 -> 1647.4064 | T8: 4 | U8: Saus Mentai | V8: 30 | W8: gr | X8: =V8*'Daftar HPP'!$G$22 -> 1995 | Z8: 4 | AA8: Saus Carbonara | AB8: 30 | AC8: gr | AD8: =AB8*'Daftar HPP'!$F$143 -> 2146.3497 | AF8: 4 | AG8: Saus Garlic | AH8: 30 | AI8: gr | AJ8: =AH8*'Daftar HPP'!$L$143 -> 1647.4064
B9: 5 | C9: Bubuk Nori | D9: 1 | E9: gr | F9: =D9*'Daftar HPP'!$G$34 -> 500 | H9: 5 | I9: Bubuk Nori | J9: 1 | K9: gr | L9: =J9*'Daftar HPP'!$G$34 -> 500 | N9: 5 | O9: Bubuk Nori | P9: 1 | Q9: gr | R9: =P9*'Daftar HPP'!$G$34 -> 500 | T9: 5 | U9: Bubuk Nori | V9: 1 | W9: gr | X9: =V9*'Daftar HPP'!$G$34 -> 500 | Z9: 5 | AA9: Bubuk Nori | AB9: 1 | AC9: gr | AD9: =AB9*'Daftar HPP'!$G$34 -> 500 | AF9: 5 | AG9: Bubuk Nori | AH9: 1 | AI9: gr | AJ9: =AH9*'Daftar HPP'!$G$34 -> 500
B10: 6 | C10: Packaging Tray | D10: 1 | E10: lembar | F10: =D10*'Daftar HPP'!$G$39 -> 1100 | H10: 6 | I10: Packaging Tray | J10: 1 | K10: lembar | L10: =J10*'Daftar HPP'!$G$39 -> 1100 | N10: 6 | O10: Packaging Tray | P10: 1 | Q10: lembar | R10: =P10*'Daftar HPP'!$G$39 -> 1100 | T10: 6 | U10: Packaging Tray | V10: 1 | W10: lembar | X10: =V10*'Daftar HPP'!$G$39 -> 1100 | Z10: 6 | AA10: Packaging Tray | AB10: 1 | AC10: lembar | AD10: =AB10*'Daftar HPP'!$G$39 -> 1100 | AF10: 6 | AG10: Packaging Tray | AH10: 1 | AI10: lembar | AJ10: =AH10*'Daftar HPP'!$G$39 -> 1100
D11: Total | F11: =SUM(F5:F10) -> 11764.69 | J11: Total | L11: =SUM(L5:L10) -> 11817.081 | P11: Total | R11: =SUM(R5:R10) -> 11467.242 | V11: Total | X11: =SUM(X5:X10) -> 16640.422 | AB11: Total | AD11: =SUM(AD5:AD10) -> 16692.813 | AH11: Total | AJ11: =SUM(AJ5:AJ10) -> 16342.973
D12: Harga Jual | F12: 23000 | J12: Harga Jual | L12: 23000 | P12: Harga Jual | R12: 23000 | V12: Harga Jual | X12: 32000 | AB12: Harga Jual | AD12: 32000 | AH12: Harga Jual | AJ12: 32000
D13: Margine | F13: =F12-F11 -> 11235.31 | J13: Margine | L13: =L12-L11 -> 11182.919 | P13: Margine | R13: =R12-R11 -> 11532.758 | V13: Margine | X13: =X12-X11 -> 15359.578 | AB13: Margine | AD13: =AD12-AD11 -> 15307.187 | AH13: Margine | AJ13: =AJ12-AJ11 -> 15657.027
B15: 2. DCC CUT TRAY SAUS KEJU + SAUS CARBONARA | H15: 6. DCC CUT TRAY SAUS MENTAI + SAUS MAYO SPICY | N15: 10. DCC CUT TRAY SAUS CARBONARA + SAUS GARLIC | T15: 2. DCC CUT TRAY SAUS KEJU + SAUS CARBONARA | Z15: 6. DCC CUT TRAY SAUS MENTAI + SAUS MAYO SPICY | AF15: 10. DCC CUT TRAY SAUS CARBONARA + SAUS GARLIC
B16: No | C16: Item | D16: Qty | E16: Satuan | F16: Jumlah | H16: No | I16: Item | J16: Qty | K16: Satuan | L16: Jumlah | N16: No | O16: Item | P16: Qty | Q16: Satuan | R16: Jumlah | T16: No | U16: Item | V16: Qty | W16: Satuan | X16: Jumlah | Z16: No | AA16: Item | AB16: Qty | AC16: Satuan | AD16: Jumlah | AF16: No | AG16: Item | AH16: Qty | AI16: Satuan | AJ16: Jumlah
B17: 1 | C17: Ayam Crispy | D17: 1 | E17: Potong | F17: =D17*'Daftar HPP'!$L$57 -> 4875.7316 | H17: 1 | I17: Ayam Crispy | J17: 1 | K17: Potong | L17: =J17*'Daftar HPP'!$L$57 -> 4875.7316 | N17: 1 | O17: Ayam Crispy | P17: 1 | Q17: Potong | R17: =P17*'Daftar HPP'!$L$57 -> 4875.7316 | T17: 1 | U17: Ayam Crispy | V17: 2 | W17: Potong | X17: =V17*'Daftar HPP'!$L$57 -> 9751.4632 | Z17: 1 | AA17: Ayam Crispy | AB17: 2 | AC17: Potong | AD17: =AB17*'Daftar HPP'!$L$57 -> 9751.4632 | AF17: 1 | AG17: Ayam Crispy | AH17: 2 | AI17: Potong | AJ17: =AH17*'Daftar HPP'!$L$57 -> 9751.4632
B18: 2 | C18: Nasi | D18: 1 | E18: Porsi | F18: =D18*'Daftar HPP'!$G$13 -> 1200 | H18: 2 | I18: Nasi | J18: 1 | K18: Porsi | L18: =J18*'Daftar HPP'!$G$13 -> 1200 | N18: 2 | O18: Nasi | P18: 1 | Q18: Porsi | R18: =P18*'Daftar HPP'!$G$13 -> 1200 | T18: 2 | U18: Nasi | V18: 1 | W18: Porsi | X18: =V18*'Daftar HPP'!$G$13 -> 1200 | Z18: 2 | AA18: Nasi | AB18: 1 | AC18: Porsi | AD18: =AB18*'Daftar HPP'!$G$13 -> 1200 | AF18: 2 | AG18: Nasi | AH18: 1 | AI18: Porsi | AJ18: =AH18*'Daftar HPP'!$G$13 -> 1200
B19: 3 | C19: Saus Keju | D19: 30 | E19: gr | F19: =D19*'Daftar HPP'!$F$152 -> 2093.9588 | H19: 3 | I19: Saus Mentai | J19: 30 | K19: gr | L19: =J19*'Daftar HPP'!$G$22 -> 1995 | N19: 3 | O19: Saus Carbonara | P19: 30 | Q19: gr | R19: =P19*'Daftar HPP'!$F$143 -> 2146.3497 | T19: 3 | U19: Saus Keju | V19: 30 | W19: gr | X19: =V19*'Daftar HPP'!$F$152 -> 2093.9588 | Z19: 3 | AA19: Saus Mentai | AB19: 30 | AC19: gr | AD19: =AB19*'Daftar HPP'!$G$22 -> 1995 | AF19: 3 | AG19: Saus Carbonara | AH19: 30 | AI19: gr | AJ19: =AH19*'Daftar HPP'!$F$143 -> 2146.3497
B20: 4 | C20: Saus Carbonara | D20: 30 | E20: gr | F20: =D20*'Daftar HPP'!$F$143 -> 2146.3497 | H20: 4 | I20: Saus Mayo Spicy | J20: 30 | K20: gr | L20: =J20*'Daftar HPP'!$L$152 -> 2144.1037 | N20: 4 | O20: Saus Garlic | P20: 30 | Q20: gr | R20: =P20*'Daftar HPP'!$L$143 -> 1647.4064 | T20: 4 | U20: Saus Carbonara | V20: 30 | W20: gr | X20: =V20*'Daftar HPP'!$F$143 -> 2146.3497 | Z20: 4 | AA20: Saus Mayo Spicy | AB20: 30 | AC20: gr | AD20: =AB20*'Daftar HPP'!$L$152 -> 2144.1037 | AF20: 4 | AG20: Saus Garlic | AH20: 30 | AI20: gr | AJ20: =AH20*'Daftar HPP'!$L$143 -> 1647.4064
B21: 5 | C21: Bubuk Nori | D21: 1 | E21: gr | F21: =D21*'Daftar HPP'!$G$34 -> 500 | H21: 5 | I21: Bubuk Nori | J21: 1 | K21: gr | L21: =J21*'Daftar HPP'!$G$34 -> 500 | N21: 5 | O21: Bubuk Nori | P21: 1 | Q21: gr | R21: =P21*'Daftar HPP'!$G$34 -> 500 | T21: 5 | U21: Bubuk Nori | V21: 1 | W21: gr | X21: =V21*'Daftar HPP'!$G$34 -> 500 | Z21: 5 | AA21: Bubuk Nori | AB21: 1 | AC21: gr | AD21: =AB21*'Daftar HPP'!$G$34 -> 500 | AF21: 5 | AG21: Bubuk Nori | AH21: 1 | AI21: gr | AJ21: =AH21*'Daftar HPP'!$G$34 -> 500
B22: 6 | C22: Packaging Tray | D22: 1 | E22: lembar | F22: =D22*'Daftar HPP'!$G$39 -> 1100 | H22: 6 | I22: Packaging Tray | J22: 1 | K22: lembar | L22: =J22*'Daftar HPP'!$G$39 -> 1100 | N22: 6 | O22: Packaging Tray | P22: 1 | Q22: lembar | R22: =P22*'Daftar HPP'!$G$39 -> 1100 | T22: 6 | U22: Packaging Tray | V22: 1 | W22: lembar | X22: =V22*'Daftar HPP'!$G$39 -> 1100 | Z22: 6 | AA22: Packaging Tray | AB22: 1 | AC22: lembar | AD22: =AB22*'Daftar HPP'!$G$39 -> 1100 | AF22: 6 | AG22: Packaging Tray | AH22: 1 | AI22: lembar | AJ22: =AH22*'Daftar HPP'!$G$39 -> 1100
D23: Total | F23: =SUM(F17:F22) -> 11916.04 | J23: Total | L23: =SUM(L17:L22) -> 11814.835 | P23: Total | R23: =SUM(R17:R22) -> 11469.488 | V23: Total | X23: =SUM(X17:X22) -> 16791.772 | AB23: Total | AD23: =SUM(AD17:AD22) -> 16690.567 | AH23: Total | AJ23: =SUM(AJ17:AJ22) -> 16345.219
D24: Harga Jual | F24: 23000 | J24: Harga Jual | L24: 23000 | P24: Harga Jual | R24: 23000 | V24: Harga Jual | X24: 32000 | AB24: Harga Jual | AD24: 32000 | AH24: Harga Jual | AJ24: 32000
D25: Margine | F25: =F24-F23 -> 11083.96 | J25: Margine | L25: =L24-L23 -> 11185.165 | P25: Margine | R25: =R24-R23 -> 11530.512 | V25: Margine | X25: =X24-X23 -> 15208.228 | AB25: Margine | AD25: =AD24-AD23 -> 15309.433 | AH25: Margine | AJ25: =AJ24-AJ23 -> 15654.781
B27: 3. DCC CUT TRAY SAUS KEJU + SAUS MAYO SPICY | H27: 7. DCC CUT TRAY SAUS MENTAI + SAUS GARLIC | T27: 3. DCC CUT TRAY SAUS KEJU + SAUS MAYO SPICY | Z27: 7. DCC CUT TRAY SAUS MENTAI + SAUS GARLIC
B28: No | C28: Item | D28: Qty | E28: Satuan | F28: Jumlah | H28: No | I28: Item | J28: Qty | K28: Satuan | L28: Jumlah | T28: No | U28: Item | V28: Qty | W28: Satuan | X28: Jumlah | Z28: No | AA28: Item | AB28: Qty | AC28: Satuan | AD28: Jumlah
B29: 1 | C29: Ayam Crispy | D29: 1 | E29: Potong | F29: =D29*'Daftar HPP'!$L$57 -> 4875.7316 | H29: 1 | I29: Ayam Crispy | J29: 1 | K29: Potong | L29: =J29*'Daftar HPP'!$L$57 -> 4875.7316 | T29: 1 | U29: Ayam Crispy | V29: 2 | W29: Potong | X29: =V29*'Daftar HPP'!$L$57 -> 9751.4632 | Z29: 1 | AA29: Ayam Crispy | AB29: 2 | AC29: Potong | AD29: =AB29*'Daftar HPP'!$L$57 -> 9751.4632
B30: 2 | C30: Nasi | D30: 1 | E30: Porsi | F30: =D30*'Daftar HPP'!$G$13 -> 1200 | H30: 2 | I30: Nasi | J30: 1 | K30: Porsi | L30: =J30*'Daftar HPP'!$G$13 -> 1200 | T30: 2 | U30: Nasi | V30: 1 | W30: Porsi | X30: =V30*'Daftar HPP'!$G$13 -> 1200 | Z30: 2 | AA30: Nasi | AB30: 1 | AC30: Porsi | AD30: =AB30*'Daftar HPP'!$G$13 -> 1200
B31: 3 | C31: Saus Keju | D31: 30 | E31: gr | F31: =D31*'Daftar HPP'!$F$152 -> 2093.9588 | H31: 3 | I31: Saus Mentai | J31: 30 | K31: gr | L31: =J31*'Daftar HPP'!$G$22 -> 1995 | T31: 3 | U31: Saus Keju | V31: 30 | W31: gr | X31: =V31*'Daftar HPP'!$F$152 -> 2093.9588 | Z31: 3 | AA31: Saus Mentai | AB31: 30 | AC31: gr | AD31: =AB31*'Daftar HPP'!$G$22 -> 1995
B32: 4 | C32: Saus Mayo Spicy | D32: 30 | E32: gr | F32: =D32*'Daftar HPP'!$L$152 -> 2144.1037 | H32: 4 | I32: Saus Garlic | J32: 30 | K32: gr | L32: =J32*'Daftar HPP'!$L$143 -> 1647.4064 | T32: 4 | U32: Saus Mayo Spicy | V32: 30 | W32: gr | X32: =V32*'Daftar HPP'!$L$152 -> 2144.1037 | Z32: 4 | AA32: Saus Garlic | AB32: 30 | AC32: gr | AD32: =AB32*'Daftar HPP'!$L$143 -> 1647.4064
B33: 5 | C33: Bubuk Nori | D33: 1 | E33: gr | F33: =D33*'Daftar HPP'!$G$34 -> 500 | H33: 5 | I33: Bubuk Nori | J33: 1 | K33: gr | L33: =J33*'Daftar HPP'!$G$34 -> 500 | T33: 5 | U33: Bubuk Nori | V33: 1 | W33: gr | X33: =V33*'Daftar HPP'!$G$34 -> 500 | Z33: 5 | AA33: Bubuk Nori | AB33: 1 | AC33: gr | AD33: =AB33*'Daftar HPP'!$G$34 -> 500
B34: 6 | C34: Packaging Tray | D34: 1 | E34: lembar | F34: =D34*'Daftar HPP'!$G$39 -> 1100 | H34: 6 | I34: Packaging Tray | J34: 1 | K34: lembar | L34: =J34*'Daftar HPP'!$G$39 -> 1100 | T34: 6 | U34: Packaging Tray | V34: 1 | W34: lembar | X34: =V34*'Daftar HPP'!$G$39 -> 1100 | Z34: 6 | AA34: Packaging Tray | AB34: 1 | AC34: lembar | AD34: =AB34*'Daftar HPP'!$G$39 -> 1100
D35: Total | F35: =SUM(F29:F34) -> 11913.794 | J35: Total | L35: =SUM(L29:L34) -> 11318.138 | V35: Total | X35: =SUM(X29:X34) -> 16789.526 | AB35: Total | AD35: =SUM(AD29:AD34) -> 16193.87
D36: Harga Jual | F36: 23000 | J36: Harga Jual | L36: 23000 | V36: Harga Jual | X36: 32000 | AB36: Harga Jual | AD36: 32000
D37: Margine | F37: =F36-F35 -> 11086.206 | J37: Margine | L37: =L36-L35 -> 11681.862 | V37: Margine | X37: =X36-X35 -> 15210.474 | AB37: Margine | AD37: =AD36-AD35 -> 15806.13
B39: 4. DCC CUT TRAY SAUS KEJU + SAUS GARLIC | H39: 8. DCC CUT TRAY SAUS MAYO SPICY + SAUS CARBONARA | T39: 4. DCC CUT TRAY SAUS KEJU + SAUS GARLIC | Z39: 8. DCC CUT TRAY SAUS MAYO SPICY + SAUS CARBONARA
B40: No | C40: Item | D40: Qty | E40: Satuan | F40: Jumlah | H40: No | I40: Item | J40: Qty | K40: Satuan | L40: Jumlah | T40: No | U40: Item | V40: Qty | W40: Satuan | X40: Jumlah | Z40: No | AA40: Item | AB40: Qty | AC40: Satuan | AD40: Jumlah
B41: 1 | C41: Ayam Crispy | D41: 1 | E41: Potong | F41: =D41*'Daftar HPP'!$L$57 -> 4875.7316 | H41: 1 | I41: Ayam Crispy | J41: 1 | K41: Potong | L41: =J41*'Daftar HPP'!$L$57 -> 4875.7316 | T41: 1 | U41: Ayam Crispy | V41: 2 | W41: Potong | X41: =V41*'Daftar HPP'!$L$57 -> 9751.4632 | Z41: 1 | AA41: Ayam Crispy | AB41: 2 | AC41: Potong | AD41: =AB41*'Daftar HPP'!$L$57 -> 9751.4632
B42: 2 | C42: Nasi | D42: 1 | E42: Porsi | F42: =D42*'Daftar HPP'!$G$13 -> 1200 | H42: 2 | I42: Nasi | J42: 1 | K42: Porsi | L42: =J42*'Daftar HPP'!$G$13 -> 1200 | T42: 2 | U42: Nasi | V42: 1 | W42: Porsi | X42: =V42*'Daftar HPP'!$G$13 -> 1200 | Z42: 2 | AA42: Nasi | AB42: 1 | AC42: Porsi | AD42: =AB42*'Daftar HPP'!$G$13 -> 1200
B43: 3 | C43: Saus Keju | D43: 30 | E43: gr | F43: =D43*'Daftar HPP'!$F$152 -> 2093.9588 | H43: 3 | I43: Saus Mayo Spicy | J43: 30 | K43: gr | L43: =J43*'Daftar HPP'!$L$152 -> 2144.1037 | T43: 3 | U43: Saus Keju | V43: 30 | W43: gr | X43: =V43*'Daftar HPP'!$F$152 -> 2093.9588 | Z43: 3 | AA43: Saus Mayo Spicy | AB43: 30 | AC43: gr | AD43: =AB43*'Daftar HPP'!$L$152 -> 2144.1037
B44: 4 | C44: Saus Garlic | D44: 30 | E44: gr | F44: =D44*'Daftar HPP'!$L$143 -> 1647.4064 | H44: 4 | I44: Saus Carbonara | J44: 30 | K44: gr | L44: =J44*'Daftar HPP'!$F$143 -> 2146.3497 | T44: 4 | U44: Saus Garlic | V44: 30 | W44: gr | X44: =V44*'Daftar HPP'!$L$143 -> 1647.4064 | Z44: 4 | AA44: Saus Carbonara | AB44: 30 | AC44: gr | AD44: =AB44*'Daftar HPP'!$F$143 -> 2146.3497
...

Sheet Minuman
B2: HPP MINUMAN D'CELUP CHICKEN CRISPY EXTRA
B4: HPP MINUMAN D'CELUP CHICKEN CRISPY EXTRA
B5: No | C5: Nama bahan | D5: qty | E5: satuan | F5: Jumlah | G5: Harga/gr
B6: 1 | C6: Bubuk Matcha | D6: 500 | E6: gr | F6: 72000 | G6: =F6/D6 -> 144
B7: 2 | C7: Susu Full Cream | D7: 1000 | E7: ml | F7: 20000 | G7: =F7/D7 -> 20
B8: 3 | C8: Gula Pasir | D8: 1000 | E8: gr | F8: 18000 | G8: =F8/D8 -> 18
B9: 4 | C9: Air | D9: 19000 | E9: ml | F9: 6000 | G9: =F9/D9 -> 0.31578947
B10: 5 | C10: Bubuk Taro | D10: 200 | E10: gr | F10: 25000 | G10: =F10/D10 -> 125
B11: 6 | C11: Sticky Milky Coklat | D11: 500 | E11: gr | F11: 45000 | G11: =F11/D11 -> 90
B12: 7 | C12: T.e.h solo | D12: 500 | E12: gr | F12: 60000 | G12: =F12/D12 -> 120
B13: 8 | C13: Es Batu | D13: 1 | E13: cup | F13: 231 | G13: =F13/D13 -> 231
B14: 9 | C14: Cup 14 oz | D14: 50 | E14: pcs | F14: 15000 | G14: =F14/D14 -> 300
B15: 10 | C15: Tutup Cup | D15: 50 | E15: pcs | F15: 15000 | G15: =F15/D15 -> 300
B16: 11 | C16: Sedotan | D16: 100 | E16: pcs | F16: 20000 | G16: =F16/D16 -> 200
B18: 1. HPP Gula Cair | H18: 2. ) HPP Basic t.e.h
B19: No | C19: Nama Bahan | D19: Qty | E19: Satuan | F19: Jumlah | H19: No | I19: Nama bahan | J19: qty | K19: satuan | L19: Jumlah
B20: 1 | C20: Gula Pasir | D20: 1000 | E20: gr | F20: =D20*$G$8 -> 18000 | H20: 1 | I20: T.e.h (16 sendok takar) | J20: 70 | K20: gr | L20: =J20*$G$12 -> 8400
B21: 2 | C21: Air Panas | D21: 500 | E21: ml | F21: =D21*$G$9 -> 157.89474 | H21: 2 | I21: Air | J21: 2000 | K21: ml | L21: =J21*$G$9 -> 631.57895
B22: 1 Resep Gula Cair bisa dipakai 44 porsi | D22: Total | F22: =SUM(F20:F20) -> 18000 | J22: Total | L22: =SUM(L20:L21) -> 9031.5789
D23: Berat Jadi | F23: 1100 | J23: T.e.h Matang / ml | L23: 1800
D24: Hpp /ml | F24: =F22/F23 -> 16.363636 | J24: hpp T.e.h / ml | L24: =L22/L23 -> 5.0175439
B26: HPP DAN HARGA JUAL MINUMAN D'CELUP CHICKEN CRISPY EXTRA
B27: 1. Minuman Matcha Latte | H27: 3. Minuman Matcha Coklat
B28: No | C28: Item | D28: Qty | E28: Satuan | F28: Jumlah | H28: No | I28: Item | J28: Qty | K28: Satuan | L28: Jumlah
B29: 1 | C29: Bubuk Matcha | D29: 20 | E29: gr | F29: =D29*$G$6 -> 2880 | H29: 1 | I29: Bubuk Matcha | J29: 20 | K29: gr | L29: =J29*$G$6 -> 2880
B30: 2 | C30: Air Panas untuk larutan Matcha | D30: 50 | E30: ml | F30: =D30*$G$9 -> 15.789474 | H30: 2 | I30: Air Panas untuk larutan Matcha | J30: 50 | K30: ml | L30: =J30*$G$9 -> 15.789474
B31: 3 | C31: Gula Cair | D31: 25 | E31: ml | F31: =D31*$F$24 -> 409.09091 | H31: 3 | I31: Gula Cair | J31: 25 | K31: ml | L31: =J31*$F$24 -> 409.09091
B32: 4 | C32: Susu Full Cream | D32: 100 | E32: ml | F32: =D32*$G$7 -> 2000 | H32: 4 | I32: Sticky Milky | J32: 15 | K32: gr | L32: =J32*$G$11 -> 1350
B33: 5 | C33: Es Batu | D33: 1 | E33: cup | F33: =D33*$G$13 -> 231 | H33: 5 | I33: Air Panas u/ larut bubuk coklat | J33: 25 | K33: ml | L33: =J33*$G$9 -> 7.8947368
B34: 6 | C34: Cup 14 oz | D34: 1 | E34: pcs | F34: =D34*$G$14 -> 300 | H34: 6 | I34: Susu Full Cream | J34: 100 | K34: ml | L34: =J34*$G$7 -> 2000
B35: 7 | C35: Tutup Cup | D35: 1 | E35: pcs | F35: =D35*$G$15 -> 300 | H35: 7 | I35: Es Batu | J35: 1 | K35: cup | L35: =J35*$G$13 -> 231
B36: 8 | C36: Sedotan | D36: 1 | E36: pcs | F36: =D36*$G$16 -> 200 | H36: 8 | I36: Cup 14 oz | J36: 1 | K36: pcs | L36: =J36*$G$14 -> 300
D37: Total HPP | F37: =SUM(F29:F36) -> 6335.8804 | H37: 9 | I37: Tutup Cup | J37: 1 | K37: pcs | L37: =J37*$G$15 -> 300
D38: Harga Jual | F38: 13000 | H38: 10 | I38: Sedotan | J38: 1 | K38: pcs | L38: =J38*$G$16 -> 200
D39: Margin | F39: =F38-F37 -> 6664.1196 | J39: Total HPP | L39: =SUM(L29:L38) -> 7693.7751
J40: Harga Jual | L40: 15000
B41: 2. Minuman Matcha Taro | J41: Margin | L41: =L40-L39 -> 7306.2249
B42: No | C42: Item | D42: Qty | E42: Satuan | F42: Jumlah
B43: 1 | C43: Bubuk Matcha | D43: 20 | E43: gr | F43: =D43*$G$6 -> 2880 | H43: 4. Minuman Es Teh
B44: 2 | C44: Air Panas untuk larutan Matcha | D44: 50 | E44: ml | F44: =D44*$G$9 -> 15.789474 | H44: No | I44: Item | J44: Qty | K44: Satuan | L44: Jumlah
...
